<?xml version="1.0"?>
<robot xmlns:xacro='http://www.ros.org/wiki/xacro'>
    <!-- 引入宏文件 -->
    <xacro:include filename='$(find robot)/urdf/project_robot/common_inertial.xacro'/>

    <!-- 此处轮子要复用 为了遵守规范 传入名字参数 -->
    <xacro:macro name='wheel_xacro' params='wheel_name xyz'> 
        <link name="${wheel_name}_link">
            <!--描述-->
            <visual>
                <!-- 旋转以正确摆放轮子 -->
                <origin xyz="0.0 0.0 0.0" rpy="1.57079 0.0 0.0"/>
                <geometry>
                        <cylinder radius="0.032" length="0.04"/>
                </geometry>
                <material name = 'black'>
                    <color rgba="0.0 0.0 0.0 0.8"/>
                </material>
            </visual>
            <collision>
                <origin xyz="0.0 0.0 0.0" rpy="1.57079 0.0 0.0"/>
                <geometry>
                        <cylinder radius="0.032" length="0.04"/>
                </geometry>
                <material name = 'black'>
                    <color rgba="0.0 0.0 0.0 0.8"/>
                </material>
            </collision>
            <!-- 惯性质量 -->
            <xacro:cylinder_inertia m='0.05' r='0.032' h='0.04'/>
        </link>

        <!-- 关节 -->
        <joint name="${wheel_name}_joint" type="continuous">
            <origin xyz="${xyz}" rpy="0.0 0.0 0.0"/>
            <parent link="base_link"/>
            <child link="${wheel_name}_link"/>
            <axis xyz="0 1 0"/>
        </joint>

        <!-- gazebo标签 扩展以显现其他属性 -->
        <gazebo reference='${wheel_name}_link'>
            <material>Gazebo/White</material>
            <!-- 切向摩擦系数 -->
            <mu1 value='20.0'/>
            <!-- 把向摩擦系数 -->
            <mu2 value='20.0'/>
            <!-- 接触刚度系数 -->
            <kp value='1000000000.0'/>
            <!-- 阻尼系数 -->
            <kd value='1.0'/>
        </gazebo>

    </xacro:macro>  
</robot>
<!-- 驱动轮部件宏 -->